Name: CVE-2010-3494
Status: Candidate
URL: http://cve.mitre.org/cgi-bin/cvename.cgi?name=CVE-2010-3494
Phase: Assigned (20100924)
Category: 
Reference: MLIST:[oss-security] 20100909 CVE Request -- Python -- accept() implementation in async core is broken => more subcases
Reference: URL:http://www.openwall.com/lists/oss-security/2010/09/09/6
Reference: MLIST:[oss-security] 20100910 Re: CVE Request -- Python -- accept() implementation in async core is broken => more subcases
Reference: URL:http://www.openwall.com/lists/oss-security/2010/09/11/2
Reference: MLIST:[oss-security] 20100922 Re: CVE Request -- Python -- accept() implementation in async core is broken => more subcases
Reference: URL:http://www.openwall.com/lists/oss-security/2010/09/22/3
Reference: MLIST:[oss-security] 20100924 Re: CVE Request -- Python -- accept() implementation in async core is broken => more subcases
Reference: URL:http://www.openwall.com/lists/oss-security/2010/09/24/3
Reference: MISC:http://bugs.python.org/issue6706
Reference: MISC:https://bugs.launchpad.net/zodb/+bug/135108
Reference: CONFIRM:http://code.google.com/p/pyftpdlib/issues/detail?id=104
Reference: CONFIRM:http://code.google.com/p/pyftpdlib/issues/detail?id=105
Reference: CONFIRM:http://code.google.com/p/pyftpdlib/source/browse/trunk/HISTORY
Reference: CONFIRM:http://code.google.com/p/pyftpdlib/source/detail?r=556
Reference: CONFIRM:http://code.google.com/p/pyftpdlib/source/diff?spec=svn556&r=556&format=side&path=/trunk/pyftpdlib/ftpserver.py

Race condition in the FTPHandler class in ftpserver.py in pyftpdlib
before 0.5.2 allows remote attackers to cause a denial of service
(daemon outage) by establishing and then immediately closing a TCP
connection, leading to the accept function having an unexpected value
of None for the address, or an ECONNABORTED, EAGAIN, or EWOULDBLOCK
error, a related issue to CVE-2010-3492.


Current Votes:
None (candidate not yet proposed)


