Name: CVE-2009-5010
Status: Candidate
URL: http://cve.mitre.org/cgi-bin/cvename.cgi?name=CVE-2009-5010
Phase: Assigned (20101019)
Category: 
Reference: MLIST:[oss-security] 20100909 CVE Request -- Python -- accept() implementation in async core is broken => more subcases
Reference: URL:http://www.openwall.com/lists/oss-security/2010/09/09/6
Reference: MLIST:[oss-security] 20100910 Re: CVE Request -- Python -- accept() implementation in async core is broken => more subcases
Reference: URL:http://www.openwall.com/lists/oss-security/2010/09/11/2
Reference: MLIST:[oss-security] 20100922 Re: CVE Request -- Python -- accept() implementation in async core is broken => more subcases
Reference: URL:http://www.openwall.com/lists/oss-security/2010/09/22/3
Reference: MLIST:[oss-security] 20100924 Re: CVE Request -- Python -- accept() implementation in async core is broken => more subcases
Reference: URL:http://www.openwall.com/lists/oss-security/2010/09/24/3
Reference: MISC:http://bugs.python.org/issue6706
Reference: MISC:https://bugs.launchpad.net/zodb/+bug/135108
Reference: CONFIRM:http://code.google.com/p/pyftpdlib/issues/detail?id=91
Reference: CONFIRM:http://code.google.com/p/pyftpdlib/source/browse/trunk/HISTORY
Reference: CONFIRM:http://code.google.com/p/pyftpdlib/source/detail?r=439
Reference: CONFIRM:http://code.google.com/p/pyftpdlib/source/diff?spec=svn439&r=439&format=side&path=/trunk/pyftpdlib/ftpserver.py

Race condition in the FTPHandler class in ftpserver.py in pyftpdlib
before 0.5.1 allows remote attackers to cause a denial of service
(daemon outage) by establishing and then immediately closing a TCP
connection, leading to the accept function having an unexpected return
value of None, a different vulnerability than CVE-2010-3494.


Current Votes:
None (candidate not yet proposed)


